<?xml version="1.0"?>
<robot name="hospitalbot">
    <link name="base_footprint">
        <collision>
            <origin	xyz="0 0 0"	rpy="0 0 0"/>
            <geometry>
                <box size="0.0001 0.0001 0.0001"/>
            </geometry>
        </collision>
        <visual>
            <origin	xyz="0 0 0"	rpy="0 0 0"/>
            <geometry>
                <box size="0.0001 0.0001 0.0001"/>
            </geometry>
        </visual>
        <inertial>
            <mass value="1e-5"/>
            <origin	xyz="0 0 0"	rpy="0 0 0"/>
            <inertia ixx="1e-6" ixy="0" ixz="0" iyy="1e-6" iyz="0" izz="1e-6"/>
        </inertial>
    </link>
    
    <link name="base_link">				
        <visual>
            <geometry>
                <box size="0.245 0.153 0.053"/>
            </geometry>
            <material name="silver">
                <color rgba="0.75 0.75 0.75 1"/>
            </material>
        </visual>
        <collision>
            <geometry>
                <box size="0.245 0.153 0.053"/>
            </geometry>
        </collision>
        <inertial>
            <mass value="0.3"/>
            <inertia ixx="0.00065545" iyy="0.00157085" izz="0.00208585" ixy="0" ixz="0" iyz="0"/>
        </inertial>
    </link>
    <joint name="base_link_joint" type="continuous">
        <axis xyz="0 0 1"/>
        <parent link="base_footprint"/>
        <child link="base_link"/>
        <origin rpy="0 0 0" xyz="0.0 0.0 0.0475"/>
    </joint>
    
    <link name="right_front_wheel">
        <visual>
            <geometry>
                <cylinder length="0.03" radius="0.03"/>
            </geometry>
            <material name="black">
                <color rgba="0 0 0 1"/>
            </material>
        </visual>
        <collision>
            <geometry>
                <cylinder length="0.03" radius="0.03"/>
            </geometry>
        </collision>
        <inertial>
            <mass value="0.125"/>
            <inertia ixx="3.75e-5" iyy="3.75e-5" izz="5.625e-5" ixy="0" ixz="0" iyz="0"/>
        </inertial>
    </link>
    <joint name="right_front_wheel_joint" type="continuous">
        <axis xyz="0 0 1"/>
        <parent link="base_link"/>
        <child link="right_front_wheel"/>
        <origin rpy="-1.5708 0 0" xyz="0.0925 -0.0915 -0.0175"/>
    </joint>

    <link name="right_rear_wheel">
        <visual>
            <geometry>
                <cylinder length="0.03" radius="0.03"/>
            </geometry>
            <material name="black">
                <color rgba="0 0 0 1"/>
            </material>
        </visual>
        <collision>
            <geometry>
                <cylinder length="0.03" radius="0.03"/>
            </geometry>
        </collision>
        <inertial>
            <mass value="0.125"/>
            <inertia ixx="3.75e-5" iyy="3.75e-5" izz="5.625e-5" ixy="0" ixz="0" iyz="0"/>
        </inertial>
    </link>
    <joint name="right_rear_wheel_joint" type="continuous">
        <axis xyz="0 0 1"/>
        <parent link="base_link"/>
        <child link="right_rear_wheel"/>
        <origin rpy="-1.5708 0 0" xyz="-0.0925 -0.0915 -0.0175"/>
    </joint>

    <link name="left_front_wheel">
        <visual>
            <geometry>
                <cylinder length="0.03" radius="0.03"/>
            </geometry>
            <material name="black">
                <color rgba="0 0 0 1"/>
            </material>
        </visual>
        <collision>
            <geometry>
                <cylinder length="0.03" radius="0.03"/>
            </geometry>
        </collision>
        <inertial>
            <mass value="0.125"/>
            <inertia ixx="3.75e-5" iyy="3.75e-5" izz="5.625e-5" ixy="0" ixz="0" iyz="0"/>
        </inertial>
    </link>
    <joint name="left_front_wheel_joint" type="continuous">
        <axis xyz="0 0 1"/>
        <parent link="base_link"/>
        <child link="left_front_wheel"/>
        <origin rpy="-1.5708 0 0" xyz="0.0925 0.0915 -0.0175"/>
    </joint>

    <link name="left_rear_wheel">
        <visual>
            <geometry>
                <cylinder length="0.03" radius="0.03"/>
            </geometry>
            <material name="black">
                <color rgba="0 0 0 1"/>
            </material>
        </visual>
        <collision>
            <geometry>
                <cylinder length="0.03" radius="0.03"/>
            </geometry>
        </collision>
        <inertial>
            <mass value="0.125"/>
            <inertia ixx="3.75e-5" iyy="3.75e-5" izz="5.625e-5" ixy="0" ixz="0" iyz="0"/>
        </inertial>
    </link>
    <joint name="left_rear_wheel_joint" type="continuous">
        <axis xyz="0 0 1"/>
        <parent link="base_link"/>
        <child link="left_rear_wheel"/>
        <origin rpy="-1.5708 0 0" xyz="-0.0925 0.0915 -0.0175"/>
    </joint>

    <link name="kinect_stand_link">
        <collision>
            <origin	xyz="0 0 0"	rpy="0 0 0"/>
            <geometry>
                <box size="0.0254 0.153 0.0635"/>
            </geometry>
        </collision>
        <visual>
            <origin	xyz="0 0 0"	rpy="0 0 0"/>
            <geometry>
                <box size="0.0254 0.153 0.0635"/>
            </geometry>
            <material name="blue">
                <color rgba="0 0 1 1"/>
            </material>
        </visual>
        <inertial>
            <mass value="0.8"/>
            <inertia ixx="0.001829417" ixy="0" ixz="0" iyy="0.000311827" iyz="0" izz="0.001603611"/>
        </inertial>
    </link>
    <joint name="kinect_stand_joint" type="continuous">
        <axis xyz="0 1 0"/>
        <origin	rpy="0 0 0"	xyz="0.06 0.0 0.05825"/>
        <parent	link="base_link"/>
        <child	link="kinect_stand_link"/>
    </joint>

    <link name="kinect_link">
        <collision>
            <origin	xyz="0 0 0"	rpy="0 0 0"/>
            <geometry>
                <box size="0.0635 0.2794 0.0381"/>
            </geometry>
        </collision>
        <visual>
            <origin	xyz="0 0 0"	rpy="0 0 0"/>
            <geometry>
                <box size="0.0635 0.2794 0.0381"/>
            </geometry>
        </visual>
        <inertial>
            <mass value="1.4"/>
            <inertia ixx="0.009276863" ixy="0" ixz="0" iyy="0.000639784" iyz="0" izz="0.009577938"/>
        </inertial>
    </link>
    <joint name="kinect_joint" type="continuous">
        <axis xyz="0 1 0"/>
        <origin	rpy="0 0 0"	xyz="0.0 0 0.0508"/>
        <parent	link="kinect_stand_link"/>
        <child	link="kinect_link"/>
    </joint>

    <link name="imu_base">
        <visual>
            <geometry>
                <box size="0.03 0.01 0.001"/>
            </geometry>
            <material name="black">
                <color rgba="0 0 1 1"/>
            </material>
        </visual>
        <collision>
            <geometry>
                <box size="0.03 0.01 0.001"/>
            </geometry>
        </collision>
        <inertial>
            <mass value="1e-5"/>
            <origin	xyz="0 0 0"	rpy="0 0 0"/>
            <inertia ixx="1e-6" ixy="0" ixz="0" iyy="1e-6" iyz="0" izz="1e-6"/>
        </inertial>
    </link>
    <joint name="imu_base_joint" type="continuous">
        <axis xyz="0 1 0"/>
        <origin	rpy="0 0 0"	xyz="0.02 0.03 0.0151"/>
        <parent	link="kinect_link"/>
        <child	link="imu_base"/>
    </joint>

    <link name="camera_rgb_frame"/>
    <joint name="camera_rgb_frame_joint" type="continuous">
        <axis xyz="0 1 0"/>
        <origin	rpy="0 0 0"	xyz="0.0 0.0 0.0"/>
        <parent	link="kinect_link"/>
        <child	link="camera_rgb_frame"/>
    </joint>

    <link name="camera_depth_frame"/>
    <joint name="camera_depth_frame_joint" type="continuous">
        <axis xyz="0 1 0"/>
        <origin	rpy="0 0 0"	xyz="0.0 0.027 0.0"/>
        <parent	link="camera_rgb_frame"/>
        <child	link="camera_depth_frame"/>
    </joint>
    
    <link name="camera_link"/>
    <joint name="camera_link_joint" type="continuous">
        <axis xyz="0 1 0"/>
        <origin	rpy="0 0 0"	xyz="0.0 -0.022 0.0"/>
        <parent	link="camera_rgb_frame"/>
        <child	link="camera_link"/>
    </joint>

    <!--<gazebo>
        <plugin	name="joint_state_publisher" filename="libgazebo_ros_joint_state_publisher.so">
            <jointName>left_front_wheel_joint, right_front_wheel_joint, left_rear_wheel_joint, right_rear_wheel_joint, camera_link_joint, camera_depth_frame_joint, camera_rgb_frame_joint, imu_base_joint, kinect_joint, kinect_stand_joint, base_link_joint</jointName>
        </plugin>
    </gazebo>-->
    <gazebo>
        <plugin name="skid_steer_drive_controller" filename="libgazebo_ros_skid_steer_drive.so">
            <updateRate>100.0</updateRate>
            <robotNamespace>/</robotNamespace>
            <leftFrontJoint>left_front_wheel_joint</leftFrontJoint>
            <rightFrontJoint>right_front_wheel_joint</rightFrontJoint>
            <leftRearJoint>left_rear_wheel_joint</leftRearJoint>
            <rightRearJoint>right_rear_wheel_joint</rightRearJoint>
            <wheelSeparation>0.183</wheelSeparation>
            <wheelDiameter>0.06</wheelDiameter>
            <robotBaseFrame>base_footprint</robotBaseFrame>
            <torque>20</torque>
            <topicName>cmd_vel</topicName>
            <broadcastTF>true</broadcastTF>
        </plugin>
    </gazebo>
    <gazebo reference="kinect_link">
        <sensor type="depth" name="kinect">
            <always_on>1</always_on>
            <visualize>true</visualize>             
            <camera>
                <horizontal_fov>1.047</horizontal_fov>  
                <image>
                <width>640</width>
                <height>480</height>
                <format>R8G8B8</format>
                </image>
                <depth_camera>

                </depth_camera>
                <clip>
                <near>0.1</near>
                <far>100</far>
                </clip>
            </camera>
            <plugin name="camera_controller" filename="libgazebo_ros_openni_kinect.so">
                <alwaysOn>true</alwaysOn>
                <updateRate>10.0</updateRate>
                <cameraName>camera</cameraName>
                <frameName>camera_depth_frame</frameName>                   
                <imageTopicName>rgb/image_raw</imageTopicName>
                <depthImageTopicName>depth/image_raw</depthImageTopicName>
                <pointCloudTopicName>depth/points</pointCloudTopicName>
                <cameraInfoTopicName>rgb/camera_info</cameraInfoTopicName>              
                <depthImageCameraInfoTopicName>depth/camera_info</depthImageCameraInfoTopicName>            
                <pointCloudCutoff>0.4</pointCloudCutoff>                
                <hackBaseline>0.07</hackBaseline>
                <distortionK1>0.0</distortionK1>
                <distortionK2>0.0</distortionK2>
                <distortionK3>0.0</distortionK3>
                <distortionT1>0.0</distortionT1>
                <distortionT2>0.0</distortionT2>
                <CxPrime>0.0</CxPrime>
                <Cx>0.0</Cx>
                <Cy>0.0</Cy>
                <focalLength>0.0</focalLength>
            </plugin>
        </sensor>
  </gazebo>
</robot>